Workbook
Name SegmentaciónDeDatos_CATEGORIA: #N/A
Name SegmentaciónDeDatos_REGION: #N/A
Name SegmentaciónDeDatos_TOTAL_VENTA: #N/A
Name SegmentaciónDeDatos_TOTAL_VENTA1: #N/A
Name SegmentaciónDeDatos_VENDEDOR: #N/A

Sheet PORTADA
F6: Título: "Proyecto Final - Curso de Excel".
F8: Nombre: Romina Ríos.
F10: Febrero 2025.

Sheet README
A3: Información del Proyecto: Análisis de ventas y desempeño de productos de tecnología para la toma de decisiones comerciales.
A5: Objetivo: Aplicar herramientas avanzadas de Excel para transformar datos brutos en un Dashboard interactivo que responda a preguntas de negocio.
A7: Fuente de los Datos: Dataset de ventas de tecnología (período 2023-2024).
A9: Versión de Excel utilizada: Microsoft Excel 2021.
A12: Criterios de Análisis y Pasos realizados:
A14: Depuración: Limpieza de duplicados y normalización de formatos en la Tabla Principal.
A16: Enriquecimiento: Creación de columnas calculadas usando funciones lógicas (SI, Y, O) y de búsqueda (BUSCARX o BUSCARV).
A18: Procesamiento: Generación de Tablas Dinámicas para agrupar ventas por categoría y país.
A20: Visualización: Diseño de un Dashboard con segmentadores de datos para permitir filtros rápidos por el usuario final.

Sheet PREGUNTAS Y RESPUESTAS
A1: ANALISIS DE DATOS
B4: Pregunta Central | C4: Objetivo de Negocio | D4: Herramienta / Resolución
B5: 1. ¿Cuál es el rendimiento de ventas por categoría? | C5: Identificar los productos estrella que generan más ingresos. | D5: Tabla Dinámica + Gráfico de Barras.
B6: 2. ¿Cómo se distribuyen las ventas por país? | C6: Determinar la presencia de mercado en cada región. | D6: Función SUMAR.SI.CONJUNTO y Segmentadores.
B7: 3. ¿Qué pedidos requieren gestión de envío prioritaria? | C7: Optimizar la logística para productos de alto valor. | D7: Función SI anidada (SI con Y).
B9: 4. ¿Cuál es el precio promedio por categoría? | C9: Analizar el posicionamiento de precios en el catálogo. | D9: Función PROMEDIO.SI + Gráfico Circular.

Sheet DATASET ORIGINAL
B2: ID_VENTA | C2: FECHA | D2: VENDEDOR | E2: PRODUCTO | F2: CATEGORIA | G2: REGION | H2: CANTIDAD | I2: PRECIO_UNITARIO | J2: DESCUENTO | K2: TOTAL_VENTA
B3: 1 | C3: 01/017/2024 | D3: CARLOS | E3: Producto | F3: Categoría | G3: Norte | H3: 11 | I3: 1725 | J3: =RANDBETWEEN(0, 15) / 100 -> 0.12 | K3: =H3*I3 -> 18975
B4: 2 | C4: 01/017/2025 | D4: LUIS | E4: Celular Samsung | F4: Tecnología | G4: Sur | H4: 2 | I4: 557 | J4: =RANDBETWEEN(0, 15) / 100 -> 0.02 | K4: =H4*I4 -> 1114
B5: 3 | C5: 01/017/2026 | D5: PEDRO | E5: Cafetera Eléctrica | F5: Hogar | G5: Centro | H5: 2 | I5: 1305 | J5: =RANDBETWEEN(0, 15) / 100 -> 0.1 | K5: =H5*I5 -> 2610
B6: 4 | C6: 01/017/2027 | D6: OSCAR | E6: Monitor 24" | F6: Oficina | G6: Este | H6: 16 | I6: 4398 | J6: =RANDBETWEEN(0, 15) / 100 -> 0.11 | K6: =H6*I6 -> 70368
B7: 5 | C7: 01/017/2028 | D7: JUAN | E7: Auriculares Bluetooth | F7: Tecnología | G7: Oeste | H7: 1 | I7: 3882 | J7: =RANDBETWEEN(0, 15) / 100 -> 0.13 | K7: =H7*I7 -> 3882
B8: 6 | C8: 01/017/2029 | D8: CARLOS | E8: Aspiradora Robot | F8: Hogar | G8: Norte | H8: 20 | I8: 4622 | J8: =RANDBETWEEN(0, 15) / 100 -> 0.15 | K8: =H8*I8 -> 92440
B9: 7 | C9: 01/017/2030 | D9: LUIS | E9: Silla Ergonómica | F9: Oficina | G9: Sur | H9: 2 | I9: 4911 | J9: =RANDBETWEEN(0, 15) / 100 -> 0.12 | K9: =H9*I9 -> 9822
B10: 8 | C10: 01/017/2031 | D10: PEDRO | E10: Tablet Lenovo | F10: Tecnología | G10: Centro | H10: 13 | I10: 1347 | J10: =RANDBETWEEN(0, 15) / 100 -> 0.02 | K10: =H10*I10 -> 17511
B11: 9 | C11: 01/017/2032 | D11: OSCAR | E11: Licuadora de Mano | F11: Hogar | G11: Este | H11: 19 | I11: 3782 | J11: =RANDBETWEEN(0, 15) / 100 -> 0.03 | K11: =H11*I11 -> 71858
B12: 10 | C12: 01/017/2033 | D12: JUAN | E12: Teclado Mecánico | F12: Oficina | G12: Oeste | H12: 5 | I12: 2020 | J12: =RANDBETWEEN(0, 15) / 100 -> 0.15 | K12: =H12*I12 -> 10100
B13: 11 | C13: 01/017/2034 | D13: CARLOS | E13: Smart TV 50" | F13: Tecnología | G13: Norte | H13: 14 | I13: 1073 | J13: =RANDBETWEEN(0, 15) / 100 -> 0.01 | K13: =H13*I13 -> 15022
B14: 12 | C14: 01/017/2035 | D14: LUIS | E14: Producto | F14: Categoría | G14: Sur | H14: 16 | I14: 524 | J14: =RANDBETWEEN(0, 15) / 100 -> 0.15 | K14: =H14*I14 -> 8384
... B504: 502 | C504: 01/017/2525 | D504: LUIS | E504: Silla Ergonómica | F504: Oficina | G504: Sur | H504: 12 | I504: 1313 | J504: =RANDBETWEEN(0, 15) / 100 -> 0.13 | K504: =H504*I504 -> 15756

Sheet TABLA PRINCIPAL
A1: ID_VENTA | B1: FECHA | C1: VENDEDOR | D1: PRODUCTO | E1: CATEGORIA | F1: REGION | G1: CANTIDAD | H1: PRECIO_UNITARIO | I1: DESCUENTO | J1: TOTAL_VENTA | K1: CALIFICACION | L1: PROVEEDOR | M1: PRIORIDAD DE ENVIO | N1: ID ALMACEN
A2: 176 | B2: 45467 | C2: CARLOS | D2: Smart TV 50" | E2: Tecnología | F2: Norte | G2: 2 | H2: 4997 | I2: 0.04 | J2: =G2*H2 -> 9994 | K2: =IF(J2>5000, "Venta Grande", "Venta Normal") -> Venta Grande | L2: =VLOOKUP(D2, AUXILIAR!$A$2:$B$16, 2, 0) -> LG Electronics | M2: =IF(AND(E2="Tecnología", J2>20000), "Prioridad Alta", IF(J2>5000, "Prioridad Media", "Prioridad Baja")) -> Prioridad Media | N2: =VLOOKUP(E2, AUXILIAR!$E$2:$F$4, 2, FALSE) -> ALM-01
A3: 2 | B3: 45293 | C3: LUIS | D3: Celular Samsung | E3: Tecnología | F3: Sur | G3: 2 | H3: 557 | I3: 0.08 | J3: =G3*H3 -> 1114 | K3: =IF(J3>5000, "Venta Grande", "Venta Normal") -> Venta Normal | L3: =VLOOKUP(D3, AUXILIAR!$A$2:$B$16, 2, 0) -> Samsung Oficial
A4: 3 | B4: 45294 | C4: PEDRO | D4: Cafetera Eléctrica | E4: Hogar | F4: Centro | G4: 2 | H4: 1305 | I4: 0.04 | J4: =G4*H4 -> 2610 | K4: =IF(J4>5000, "Venta Grande", "Venta Normal") -> Venta Normal | L4: =VLOOKUP(D4, AUXILIAR!$A$2:$B$16, 2, 0) -> LG Electronics
A5: 90 | B5: 45381 | C5: JUAN | D5: Celular Samsung | E5: Tecnología | F5: Oeste | G5: 8 | H5: 4971 | I5: 0.11 | J5: =G5*H5 -> 39768 | K5: =IF(J5>5000, "Venta Grande", "Venta Normal") -> Venta Grande | L5: =VLOOKUP(D5, AUXILIAR!$A$2:$B$16, 2, 0) -> Samsung Oficial | M5: =IF(AND(E5="Tecnología", J5>20000), "Prioridad Alta", IF(J5>5000, "Prioridad Media", "Prioridad Baja")) -> Prioridad Alta | N5: =VLOOKUP(E5, AUXILIAR!$E$2:$F$4, 2, FALSE) -> ALM-01
A6: 5 | B6: 45296 | C6: JUAN | D6: Auriculares Bluetooth | E6: Tecnología | F6: Oeste | G6: 1 | H6: 3882 | I6: 0.01 | J6: =G6*H6 -> 3882 | K6: =IF(J6>5000, "Venta Grande", "Venta Normal") -> Venta Normal | L6: =VLOOKUP(D6, AUXILIAR!$A$2:$B$16, 2, 0) -> LG Electronics
A7: 457 | B7: 45748 | C7: LUIS | D7: Aspiradora Robot | E7: Hogar | F7: Sur | G7: 4 | H7: 4967 | I7: 0.12 | J7: =G7*H7 -> 19868 | K7: =IF(J7>5000, "Venta Grande", "Venta Normal") -> Venta Grande | L7: =VLOOKUP(D7, AUXILIAR!$A$2:$B$16, 2, 0) -> Samsung Oficial | M7: =IF(AND(E7="Tecnología", J7>20000), "Prioridad Alta", IF(J7>5000, "Prioridad Media", "Prioridad Baja")) -> Prioridad Media | N7: =VLOOKUP(E7, AUXILIAR!$E$2:$F$4, 2, FALSE) -> ALM-02
A8: 170 | B8: 45461 | C8: JUAN | D8: Auriculares Bluetooth | E8: Tecnología | F8: Oeste | G8: 10 | H8: 4964 | I8: 0.03 | J8: =G8*H8 -> 49640 | K8: =IF(J8>5000, "Venta Grande", "Venta Normal") -> Venta Grande | L8: =VLOOKUP(D8, AUXILIAR!$A$2:$B$16, 2, 0) -> LG Electronics | M8: =IF(AND(E8="Tecnología", J8>20000), "Prioridad Alta", IF(J8>5000, "Prioridad Media", "Prioridad Baja")) -> Prioridad Alta | N8: =VLOOKUP(E8, AUXILIAR!$E$2:$F$4, 2, FALSE) -> ALM-01
A9: 140 | B9: 45431 | C9: JUAN | D9: Tablet Lenovo | E9: Tecnología | F9: Oeste | G9: 14 | H9: 4961 | I9: 0.07 | J9: =G9*H9 -> 69454 | K9: =IF(J9>5000, "Venta Grande", "Venta Normal") -> Venta Grande | L9: =VLOOKUP(D9, AUXILIAR!$A$2:$B$16, 2, 0) -> Office Design | M9: =IF(AND(E9="Tecnología", J9>20000), "Prioridad Alta", IF(J9>5000, "Prioridad Media", "Prioridad Baja")) -> Prioridad Alta | N9: =VLOOKUP(E9, AUXILIAR!$E$2:$F$4, 2, FALSE) -> ALM-01
A10: 97 | B10: 45388 | C10: LUIS | D10: Licuadora de Mano | E10: Hogar | F10: Sur | G10: 9 | H10: 4932 | I10: 0.03 | J10: =G10*H10 -> 44388 | K10: =IF(J10>5000, "Venta Grande", "Venta Normal") -> Venta Grande | L10: =VLOOKUP(D10, AUXILIAR!$A$2:$B$16, 2, 0) -> LG Electronics | M10: =IF(AND(E10="Tecnología", J10>20000), "Prioridad Alta", IF(J10>5000, "Prioridad Media", "Prioridad Baja")) -> Prioridad Media | N10: =VLOOKUP(E10, AUXILIAR!$E$2:$F$4, 2, FALSE) -> ALM-02
A11: 96 | B11: 45387 | C11: CARLOS | D11: Tablet Lenovo | E11: Tecnología | F11: Norte | G11: 8 | H11: 4912 | I11: 0.12 | J11: =G11*H11 -> 39296 | K11: =IF(J11>5000, "Venta Grande", "Venta Normal") -> Venta Grande | L11: =VLOOKUP(D11, AUXILIAR!$A$2:$B$16, 2, 0) -> Office Design | M11: =IF(AND(E11="Tecnología", J11>20000), "Prioridad Alta", IF(J11>5000, "Prioridad Media", "Prioridad Baja")) -> Prioridad Alta | N11: =VLOOKUP(E11, AUXILIAR!$E$2:$F$4, 2, FALSE) -> ALM-01
A12: 7 | B12: 45298 | C12: LUIS | D12: Silla Ergonómica | E12: Oficina | F12: Sur | G12: 2 | H12: 4911 | I12: 0.11 | J12: =G12*H12 -> 9822 | K12: =IF(J12>5000, "Venta Grande", "Venta Normal") -> Venta Grande | L12: =VLOOKUP(D12, AUXILIAR!$A$2:$B$16, 2, 0) -> LG Electronics | M12: =IF(AND(E12="Tecnología", J12>20000), "Prioridad Alta", IF(J12>5000, "Prioridad Media", "Prioridad Baja")) -> Prioridad Media | N12: =VLOOKUP(E12, AUXILIAR!$E$2:$F$4, 2, FALSE) -> ALM-03
A13: 416 | B13: 45707 | C13: CARLOS | D13: Licuadora de Mano | E13: Hogar | F13: Norte | G13: 14 | H13: 4896 | I13: 0.14 | J13: =G13*H13 -> 68544 | K13: =IF(J13>5000, "Venta Grande", "Venta Normal") -> Venta Grande | L13: =VLOOKUP(D13, AUXILIAR!$A$2:$B$16, 2, 0) -> LG Electronics | M13: =IF(AND(E13="Tecnología", J13>20000), "Prioridad Alta", IF(J13>5000, "Prioridad Media", "Prioridad Baja")) -> Prioridad Media | N13: =VLOOKUP(E13, AUXILIAR!$E$2:$F$4, 2, FALSE) -> ALM-02
A14: 482 | B14: 45773 | C14: LUIS | D14: Licuadora de Mano | E14: Hogar | F14: Sur | G14: 15 | H14: 4883 | I14: 0.12 | J14: =G14*H14 -> 73245 | K14: =IF(J14>5000, "Venta Grande", "Venta Normal") -> Venta Grande | L14: =VLOOKUP(D14, AUXILIAR!$A$2:$B$16, 2, 0) -> LG Electronics | M14: =IF(AND(E14="Tecnología", J14>20000), "Prioridad Alta", IF(J14>5000, "Prioridad Media", "Prioridad Baja")) -> Prioridad Media | N14: =VLOOKUP(E14, AUXILIAR!$E$2:$F$4, 2, FALSE) -> ALM-02
A15: 145 | B15: 45436 | C15: JUAN | D15: Celular Samsung | E15: Tecnología | F15: Oeste | G15: 13 | H15: 4882 | I15: 0.08 | J15: =G15*H15 -> 63466 | K15: =IF(J15>5000, "Venta Grande", "Venta Normal") -> Venta Grande | L15: =VLOOKUP(D15, AUXILIAR!$A$2:$B$16, 2, 0) -> Samsung Oficial | M15: =IF(AND(E15="Tecnología", J15>20000), "Prioridad Alta", IF(J15>5000, "Prioridad Media", "Prioridad Baja")) -> Prioridad Alta | N15: =VLOOKUP(E15, AUXILIAR!$E$2:$F$4, 2, FALSE) -> ALM-01
A16: 241 | B16: 45532 | C16: CARLOS | D16: Teclado Mecánico | E16: Oficina | F16: Norte | G16: 6 | H16: 4875 | I16: 0.12 | J16: =G16*H16 -> 29250 | K16: =IF(J16>5000, "Venta Grande", "Venta Normal") -> Venta Grande | L16: =VLOOKUP(D16, AUXILIAR!$A$2:$B$16, 2, 0) -> Samsung Oficial | M16: =IF(AND(E16="Tecnología", J16>20000), "Prioridad Alta", IF(J16>5000, "Prioridad Media", "Prioridad Baja")) -> Prioridad Media | N16: =VLOOKUP(E16, AUXILIAR!$E$2:$F$4, 2, FALSE) -> ALM-03
A17: 39 | B17: 45330 | C17: OSCAR | D17: Aspiradora Robot | E17: Hogar | F17: Este | G17: 16 | H17: 4849 | I17: 0.04 | J17: =G17*H17 -> 77584 | K17: =IF(J17>5000, "Venta Grande", "Venta Normal") -> Venta Grande | L17: =VLOOKUP(D17, AUXILIAR!$A$2:$B$16, 2, 0) -> Samsung Oficial | M17: =IF(AND(E17="Tecnología", J17>20000), "Prioridad Alta", IF(J17>5000, "Prioridad Media", "Prioridad Baja")) -> Prioridad Media | N17: =VLOOKUP(E17, AUXILIAR!$E$2:$F$4, 2, FALSE) -> ALM-02
A18: 17 | B18: 45308 | C18: LUIS | D18: Aspiradora Robot | E18: Hogar | F18: Sur | G18: 1 | H18: 3447 | I18: 0.09 | J18: =G18*H18 -> 3447 | K18: =IF(J18>5000, "Venta Grande", "Venta Normal") -> Venta Normal | L18: =VLOOKUP(D18, AUXILIAR!$A$2:$B$16, 2, 0) -> Samsung Oficial
A19: 247 | B19: 45538 | C19: LUIS | D19: Auriculares Bluetooth | E19: Tecnología | F19: Sur | G19: 20 | H19: 4844 | I19: 0.04 | J19: =G19*H19 -> 96880 | K19: =IF(J19>5000, "Venta Grande", "Venta Normal") -> Venta Grande | L19: =VLOOKUP(D19, AUXILIAR!$A$2:$B$16, 2, 0) -> LG Electronics | M19: =IF(AND(E19="Tecnología", J19>20000), "Prioridad Alta", IF(J19>5000, "Prioridad Media", "Prioridad Baja")) -> Prioridad Alta | N19: =VLOOKUP(E19, AUXILIAR!$E$2:$F$4, 2, FALSE) -> ALM-01
A20: 284 | B20: 45575 | C20: OSCAR | D20: Licuadora de Mano | E20: Hogar | F20: Este | G20: 19 | H20: 4833 | I20: 0.13 | J20: =G20*H20 -> 91827 | K20: =IF(J20>5000, "Venta Grande", "Venta Normal") -> Venta Grande | L20: =VLOOKUP(D20, AUXILIAR!$A$2:$B$16, 2, 0) -> LG Electronics | M20: =IF(AND(E20="Tecnología", J20>20000), "Prioridad Alta", IF(J20>5000, "Prioridad Media", "Prioridad Baja")) -> Prioridad Media | N20: =VLOOKUP(E20, AUXILIAR!$E$2:$F$4, 2, FALSE) -> ALM-02
A21: 209 | B21: 45500 | C21: OSCAR | D21: Smart TV 50" | E21: Tecnología | F21: Este | G21: 13 | H21: 4819 | I21: 0.08 | J21: =G21*H21 -> 62647 | K21: =IF(J21>5000, "Venta Grande", "Venta Normal") -> Venta Grande | L21: =VLOOKUP(D21, AUXILIAR!$A$2:$B$16, 2, 0) -> LG Electronics | M21: =IF(AND(E21="Tecnología", J21>20000), "Prioridad Alta", IF(J21>5000, "Prioridad Media", "Prioridad Baja")) -> Prioridad Alta | N21: =VLOOKUP(E21, AUXILIAR!$E$2:$F$4, 2, FALSE) -> ALM-01
A22: 382 | B22: 45673 | C22: LUIS | D22: Tablet Lenovo | E22: Tecnología | F22: Sur | G22: 19 | H22: 4817 | I22: 0.07 | J22: =G22*H22 -> 91523 | K22: =IF(J22>5000, "Venta Grande", "Venta Normal") -> Venta Grande | L22: =VLOOKUP(D22, AUXILIAR!$A$2:$B$16, 2, 0) -> Office Design | M22: =IF(AND(E22="Tecnología", J22>20000), "Prioridad Alta", IF(J22>5000, "Prioridad Media", "Prioridad Baja")) -> Prioridad Alta | N22: =VLOOKUP(E22, AUXILIAR!$E$2:$F$4, 2, FALSE) -> ALM-01
A23: 154 | B23: 45445 | C23: OSCAR | D23: Smart TV 50" | E23: Tecnología | F23: Este | G23: 16 | H23: 4789 | I23: 0.06 | J23: =G23*H23 -> 76624 | K23: =IF(J23>5000, "Venta Grande", "Venta Normal") -> Venta Grande | L23: =VLOOKUP(D23, AUXILIAR!$A$2:$B$16, 2, 0) -> LG Electronics | M23: =IF(AND(E23="Tecnología", J23>20000), "Prioridad Alta", IF(J23>5000, "Prioridad Media", "Prioridad Baja")) -> Prioridad Alta | N23: =VLOOKUP(E23, AUXILIAR!$E$2:$F$4, 2, FALSE) -> ALM-01
A24: 23 | B24: 45314 | C24: PEDRO | D24: Smart TV 50" | E24: Tecnología | F24: Centro | G24: 2 | H24: 272 | I24: 0.09 | J24: =G24*H24 -> 544 | K24: =IF(J24>5000, "Venta Grande", "Venta Normal") -> Venta Normal | L24: =VLOOKUP(D24, AUXILIAR!$A$2:$B$16, 2, 0) -> LG Electronics
A25: 208 | B25: 45499 | C25: PEDRO | D25: Teclado Mecánico | E25: Oficina | F25: Centro | G25: 7 | H25: 4787 | I25: 0.14 | J25: =G25*H25 -> 33509 | K25: =IF(J25>5000, "Venta Grande", "Venta Normal") -> Venta Grande | L25: =VLOOKUP(D25, AUXILIAR!$A$2:$B$16, 2, 0) -> Samsung Oficial | M25: =IF(AND(E25="Tecnología", J25>20000), "Prioridad Alta", IF(J25>5000, "Prioridad Media", "Prioridad Baja")) -> Prioridad Media | N25: =VLOOKUP(E25, AUXILIAR!$E$2:$F$4, 2, FALSE) -> ALM-03
A26: 50 | B26: 45341 | C26: JUAN | D26: Aspiradora Robot | E26: Hogar | F26: Oeste | G26: 14 | H26: 4780 | I26: 0.1 | J26: =G26*H26 -> 66920 | K26: =IF(J26>5000, "Venta Grande", "Venta Normal") -> Venta Grande | L26: =VLOOKUP(D26, AUXILIAR!$A$2:$B$16, 2, 0) -> Samsung Oficial | M26: =IF(AND(E26="Tecnología", J26>20000), "Prioridad Alta", IF(J26>5000, "Prioridad Media", "Prioridad Baja")) -> Prioridad Media | N26: =VLOOKUP(E26, AUXILIAR!$E$2:$F$4, 2, FALSE) -> ALM-02
A27: 458 | B27: 45749 | C27: PEDRO | D27: Silla Ergonómica | E27: Oficina | F27: Centro | G27: 15 | H27: 4777 | I27: 0.02 | J27: =G27*H27 -> 71655 | K27: =IF(J27>5000, "Venta Grande", "Venta Normal") -> Venta Grande | L27: =VLOOKUP(D27, AUXILIAR!$A$2:$B$16, 2, 0) -> LG Electronics | M27: =IF(AND(E27="Tecnología", J27>20000), "Prioridad Alta", IF(J27>5000, "Prioridad Media", "Prioridad Baja")) -> Prioridad Media | N27: =VLOOKUP(E27, AUXILIAR!$E$2:$F$4, 2, FALSE) -> ALM-03
A28: 125 | B28: 45416 | C28: JUAN | D28: Monitor 24" | E28: Oficina | F28: Oeste | G28: 4 | H28: 4769 | I28: 0.1 | J28: =G28*H28 -> 19076 | K28: =IF(J28>5000, "Venta Grande", "Venta Normal") -> Venta Grande | L28: =VLOOKUP(D28, AUXILIAR!$A$2:$B$16, 2, 0) -> Office Design | M28: =IF(AND(E28="Tecnología", J28>20000), "Prioridad Alta", IF(J28>5000, "Prioridad Media", "Prioridad Baja")) -> Prioridad Media | N28: =VLOOKUP(E28, AUXILIAR!$E$2:$F$4, 2, FALSE) -> ALM-03
A29: 49 | B29: 45340 | C29: OSCAR | D29: Auriculares Bluetooth | E29: Tecnología | F29: Este | G29: 7 | H29: 4763 | I29: 0.11 | J29: =G29*H29 -> 33341 | K29: =IF(J29>5000, "Venta Grande", "Venta Normal") -> Venta Grande | L29: =VLOOKUP(D29, AUXILIAR!$A$2:$B$16, 2, 0) -> LG Electronics | M29: =IF(AND(E29="Tecnología", J29>20000), "Prioridad Alta", IF(J29>5000, "Prioridad Media", "Prioridad Baja")) -> Prioridad Alta | N29: =VLOOKUP(E29, AUXILIAR!$E$2:$F$4, 2, FALSE) -> ALM-01
A30: 213 | B30: 45504 | C30: PEDRO | D30: Monitor 24" | E30: Oficina | F30: Centro | G30: 13 | H30: 4758 | I30: 0.12 | J30: =G30*H30 -> 61854 | K30: =IF(J30>5000, "Venta Grande", "Venta Normal") -> Venta Grande | L30: =VLOOKUP(D30, AUXILIAR!$A$2:$B$16, 2, 0) -> Office Design | M30: =IF(AND(E30="Tecnología", J30>20000), "Prioridad Alta", IF(J30>5000, "Prioridad Media", "Prioridad Baja")) -> Prioridad Media | N30: =VLOOKUP(E30, AUXILIAR!$E$2:$F$4, 2, FALSE) -> ALM-03
A31: 30 | B31: 45321 | C31: JUAN | D31: Tablet Lenovo | E31: Tecnología | F31: Oeste | G31: 10 | H31: 349 | I31: 0.04 | J31: =G31*H31 -> 3490 | K31: =IF(J31>5000, "Venta Grande", "Venta Normal") -> Venta Normal | L31: =VLOOKUP(D31, AUXILIAR!$A$2:$B$16, 2, 0) -> Office Design
A32: 271 | B32: 45562 | C32: CARLOS | D32: Silla Ergonómica | E32: Oficina | F32: Norte | G32: 7 | H32: 4744 | I32: 0.1 | J32: =G32*H32 -> 33208 | K32: =IF(J32>5000, "Venta Grande", "Venta Normal") -> Venta Grande | L32: =VLOOKUP(D32, AUXILIAR!$A$2:$B$16, 2, 0) -> LG Electronics | M32: =IF(AND(E32="Tecnología", J32>20000), "Prioridad Alta", IF(J32>5000, "Prioridad Media", "Prioridad Baja")) -> Prioridad Media | N32: =VLOOKUP(E32, AUXILIAR!$E$2:$F$4, 2, FALSE) -> ALM-03
A33: 197 | B33: 45488 | C33: LUIS | D33: Teclado Mecánico | E33: Oficina | F33: Sur | G33: 13 | H33: 4726 | I33: 0.11 | J33: =G33*H33 -> 61438 | K33: =IF(J33>5000, "Venta Grande", "Venta Normal") -> Venta Grande | L33: =VLOOKUP(D33, AUXILIAR!$A$2:$B$16, 2, 0) -> Samsung Oficial | M33: =IF(AND(E33="Tecnología", J33>20000), "Prioridad Alta", IF(J33>5000, "Prioridad Media", "Prioridad Baja")) -> Prioridad Media | N33: =VLOOKUP(E33, AUXILIAR!$E$2:$F$4, 2, FALSE) -> ALM-03
A34: 33 | B34: 45324 | C34: PEDRO | D34: Smart TV 50" | E34: Tecnología | F34: Centro | G34: 1 | H34: 3859 | I34: 0.15 | J34: =G34*H34 -> 3859 | K34: =IF(J34>5000, "Venta Grande", "Venta Normal") -> Venta Normal | L34: =VLOOKUP(D34, AUXILIAR!$A$2:$B$16, 2, 0) -> LG Electronics
A35: 366 | B35: 45657 | C35: CARLOS | D35: Cafetera Eléctrica | E35: Hogar | F35: Norte | G35: 2 | H35: 4721 | I35: 0.1 | J35: =G35*H35 -> 9442 | K35: =IF(J35>5000, "Venta Grande", "Venta Normal") -> Venta Grande | L35: =VLOOKUP(D35, AUXILIAR!$A$2:$B$16, 2, 0) -> LG Electronics | M35: =IF(AND(E35="Tecnología", J35>20000), "Prioridad Alta", IF(J35>5000, "Prioridad Media", "Prioridad Baja")) -> Prioridad Media | N35: =VLOOKUP(E35, AUXILIAR!$E$2:$F$4, 2, FALSE) -> ALM-02
A36: 155 | B36: 45446 | C36: JUAN | D36: Smart TV 50" | E36: Tecnología | F36: Oeste | G36: 10 | H36: 4686 | I36: 0.05 | J36: =G36*H36 -> 46860 | K36: =IF(J36>5000, "Venta Grande", "Venta Normal") -> Venta Grande | L36: =VLOOKUP(D36, AUXILIAR!$A$2:$B$16, 2, 0) -> LG Electronics | M36: =IF(AND(E36="Tecnología", J36>20000), "Prioridad Alta", IF(J36>5000, "Prioridad Media", "Prioridad Baja")) -> Prioridad Alta | N36: =VLOOKUP(E36, AUXILIAR!$E$2:$F$4, 2, FALSE) -> ALM-01
A37: 36 | B37: 45327 | C37: CARLOS | D37: Cafetera Eléctrica | E37: Hogar | F37: Norte | G37: 7 | H37: 146 | I37: 0.09 | J37: =G37*H37 -> 1022 | K37: =IF(J37>5000, "Venta Grande", "Venta Normal") -> Venta Normal | L37: =VLOOKUP(D37, AUXILIAR!$A$2:$B$16, 2, 0) -> LG Electronics
A38: 37 | B38: 45328 | C38: LUIS | D38: Monitor 24" | E38: Oficina | F38: Sur | G38: 3 | H38: 941 | I38: 0.03 | J38: =G38*H38 -> 2823 | K38: =IF(J38>5000, "Venta Grande", "Venta Normal") -> Venta Normal | L38: =VLOOKUP(D38, AUXILIAR!$A$2:$B$16, 2, 0) -> Office Design
A39: 354 | B39: 45645 | C39: OSCAR | D39: Celular Samsung | E39: Tecnología | F39: Este | G39: 6 | H39: 4656 | I39: 0.15 | J39: =G39*H39 -> 27936 | K39: =IF(J39>5000, "Venta Grande", "Venta Normal") -> Venta Grande | L39: =VLOOKUP(D39, AUXILIAR!$A$2:$B$16, 2, 0) -> Samsung Oficial | M39: =IF(AND(E39="Tecnología", J39>20000), "Prioridad Alta", IF(J39>5000, "Prioridad Media", "Prioridad Baja")) -> Prioridad Alta | N39: =VLOOKUP(E39, AUXILIAR!$E$2:$F$4, 2, FALSE) -> ALM-01
A40: 270 | B40: 45561 | C40: JUAN | D40: Aspiradora Robot | E40: Hogar | F40: Oeste | G40: 19 | H40: 4648 | I40: 0.09 | J40: =G40*H40 -> 88312 | K40: =IF(J40>5000, "Venta Grande", "Venta Normal") -> Venta Grande | L40: =VLOOKUP(D40, AUXILIAR!$A$2:$B$16, 2, 0) -> Samsung Oficial | M40: =IF(AND(E40="Tecnología", J40>20000), "Prioridad Alta", IF(J40>5000, "Prioridad Media", "Prioridad Baja")) -> Prioridad Media | N40: =VLOOKUP(E40, AUXILIAR!$E$2:$F$4, 2, FALSE) -> ALM-02
...

Sheet TABLA DINAMICA
A3: Etiquetas de fila | B3: Suma de TOTAL_VENTA
A4: Centro | B4: 2673191
A5: Este | B5: 2723370
A6: Norte | B6: 2681744
A7: Oeste | B7: 2783006
A8: Sur | B8: 2703682
A9: Total general | B9: 13564993
A11: Etiquetas de fila | B11: Suma de TOTAL_VENTA
A12: Tecnología | B12: 6065320
A13: Oficina | B13: 3514129
A14: Hogar | B14: 3985544
A15: Total general | B15: 13564993
A17: Etiquetas de fila | B17: Suma de TOTAL_VENTA
A18: Prioridad Alta | B18: 5016839
A19: Prioridad Media | B19: 8316339
A20: Total general | B20: 13333178

Sheet DASHBOARD
A1: VENTAS TOTALES | F1: PRODUCTOS VENDIDOS | L1: TOTAL DE VENTAS
B2: =SUM('TABLA PRINCIPAL'!J:J) -> 27129986 | G2: =SUM('TABLA PRINCIPAL'!G:G) -> 5315 | L2: =COUNTA('TABLA PRINCIPAL'!A:A)-1 -> 502

Sheet AUXILIAR
A1: Producto | B1: Proveedor | E1: Celda E (Categoría) | F1: Celda F (ID_Almacén)
A2: Smart TV 50" | B2: LG Electronics | E2: Tecnología | F2: ALM-01
A3: Celular Samsung | B3: Samsung Oficial | E3: Hogar | F3: ALM-02
A4: Cafetera Eléctrica | B4: LG Electronics | E4: Oficina | F4: ALM-03
A5: Monitor 24" | B5: Office Design
A6: Auriculares Bluetooth | B6: LG Electronics
A7: Aspiradora Robot | B7: Samsung Oficial
A8: Silla Ergonómica | B8: LG Electronics
A9: Tablet Lenovo | B9: Office Design
A10: Licuadora de Mano | B10: LG Electronics
A11: Teclado Mecánico | B11: Samsung Oficial
A12: Smart TV 50" | B12: LG Electronics
A14: SUR
A15: CENTRO
A16: ESTE
A17: OESTE
